<mujoco model="hunter">
  <compiler angle="radian" meshdir="meshes/"/>

  <default>
    <default class="hunter">
      <joint damping="1" armature="0.1"/>
      <default class="visual">
        <geom type="mesh" contype="0" conaffinity="0" group="1" density="0" rgba="0.75294 0.75294 0.75294 1"/>
      </default>
      <default class="collision">
        <geom group="3" mass="0" density="0"/>
        <default class="foot">
          <geom type="sphere" size=".001"/>
          <default class="foot1">
            <geom size="0.001" contype="0" conaffinity="0" density="0"/>
          </default>
          <default class="foot2">
            <geom size="0.001"/>
          </default>
          <default class="foot3">
            <geom size="0.001"/>
          </default>
          <default class="foot4">
            <geom size="0.001"/>
          </default>
        </default>
      </default>
      <site size="0.001" rgba="0.5 0.5 0.5 0.3" group="4"/>
    </default>
    <default class="hunter_motor">
      <motor gear="1" ctrllimited="true" ctrlrange="-100  100" />
    </default>
  </default>

    <asset>
        <mesh name="base_link" file="base_link.stl" />
        <mesh name="l_hip_pitch_link" file="l_hip_pitch_link.stl" />
        <mesh name="l_hip_roll_link" file="l_hip_roll_link.stl" />
        <mesh name="l_thigh_link" file="l_thigh_link.stl" />
        <mesh name="l_calf_link" file="l_calf_link.stl" />
        <mesh name="l_ankle_pitch_link" file="l_ankle_pitch_link.stl" />
        <mesh name="l_ankle_roll_link" file="l_ankle_roll_link.stl" />
        <mesh name="r_hip_pitch_link" file="r_hip_pitch_link.stl" />
        <mesh name="r_hip_roll_link" file="r_hip_roll_link.stl" />
        <mesh name="r_thigh_link" file="r_thigh_link.stl" />
        <mesh name="r_calf_link" file="r_calf_link.stl" />
        <mesh name="r_ankle_pitch_link" file="r_ankle_pitch_link.stl" />
        <mesh name="r_ankle_roll_link" file="r_ankle_roll_link.stl" />

    </asset>

  <worldbody>
        <light mode="targetbodycom" target="base_link" pos="2 0 2.5"/>
        <body name="base_link" pos="0 0 0.5" childclass="hunter">
            <freejoint/>
            <inertial pos="0.00080912 -8.753E-05 0.03920549" quat="1 0 0 0" mass="1.82" diaginertia="0.00829787 0.00916809 0.00411404" />
            <geom type="mesh" contype="0" conaffinity="0" group="1" rgba="1 1 1 1" mesh="base_link" />
            <geom size="0.1 0.1 0.1" pos="0 0 0.08" type="box" rgba="1 1 1 0" />
            <site name="imu" pos="0 0 0"/>
            <geom type="mesh" contype="0" conaffinity="0" group="1" rgba="0.79216 0.81961 0.93333 1" mesh="base_link" />
            <geom size="0.05 0.05 0.05" pos="0 0 0.08" type="box" rgba="0.79216 0.81961 0.93333 1" />
            <geom size="0.0075 0.0075 0.002" type="box" contype="0" conaffinity="0" group="1" />
            <body name="leg_l1_link" pos="-0.0028186 0.0482 -0.031">
                <inertial pos="0.0010765 0.030923 -0.00028479" quat="0.0142487 0.688307 0.103743 0.717822" mass="0.37475" diaginertia="0.000203872 0.000193061 0.000188317" />
                <joint name="leg_l1_joint" pos="0 0 0" axis="0 1 0" limited="true" range="-1.5 1.5" />
                <geom type="mesh" contype="0" conaffinity="0" group="1" rgba="0.89804 0.91765 0.92941 1" mesh="l_hip_pitch_link" />
                <geom size="0.0005 0.0005 0.0005" type="box" rgba="0.89804 0.91765 0.92941 1" />
                <body name="leg_l2_link" pos="0.0245 0.032 0">
                    <inertial pos="-0.025798 0.00024695 -0.059965" quat="0.712751 -0.0772627 -0.0796054 0.692589" mass="0.41506" diaginertia="0.000442349 0.000383181 0.000238861" />
                    <joint name="leg_l2_joint" pos="0 0 0" axis="1 0 0" limited="true" range="-1.5 1.5" />
                    <geom type="mesh" contype="0" conaffinity="0" group="1" rgba="0.79216 0.81961 0.93333 1" mesh="l_hip_roll_link" />
                    <geom size="0.0005 0.0005 0.0005" type="box" rgba="0.79216 0.81961 0.93333 1" />
                    <body name="leg_l3_link" pos="-0.0245 0 -0.0935">
                        <inertial pos="0 -0.00286926 -0.0254156" quat="0.632955 0.774189 0 0" mass="0.120981" diaginertia="0.00013405 0.000100222 6.29478e-05" />
                        <joint name="leg_l3_joint" pos="0 0 0" axis="0 0 1" limited="true" range="-1.5 1.5" />
                        <geom type="mesh" contype="0" conaffinity="0" group="1" rgba="0.89804 0.91765 0.92941 1" mesh="l_thigh_link" />
                        <geom size="0.0005 0.0005 0.0005" type="box" rgba="0.89804 0.91765 0.92941 1" />
                        <body name="leg_l4_link" pos="0 0.0275 -0.046">
                            <inertial pos="4.686e-05 -0.024357 -0.0698324" quat="0.705543 -0.000997519 -0.00114574 0.708665" mass="0.760191" diaginertia="0.00327684 0.0032569 0.000316823" />
                            <joint name="leg_l4_joint" pos="0 0 0" axis="0 1 0" limited="true" range="-1 3" />
                            <geom type="mesh" contype="0" conaffinity="0" group="1" rgba="0.75294 0.75294 0.75294 1" mesh="l_calf_link" />
                            <geom size="0.0005 0.0005 0.0005" type="box" rgba="0.75294 0.75294 0.75294 1" />
                            <body name="leg_l5_link" pos="0 0 -0.14">
                                <inertial pos="0.0257768 -0.0285458 0" quat="0.52988 0.468217 -0.52988 0.468217" mass="0.132231" diaginertia="0.00013716 9.89216e-05 6.97784e-05" />
                                <joint name="leg_l5_joint" pos="0 0 0" axis="0 1 0" limited="true" range="-1 1" />
                                <geom type="mesh" contype="0" conaffinity="0" group="1" rgba="0.89804 0.91765 0.92941 1" mesh="l_ankle_pitch_link" />
                                <geom size="0.0005 0.0005 0.0005" type="box" rgba="0.89804 0.91765 0.92941 1" />
                                <body name="l_ankle_roll_link" pos="0.051 -0.0275 0">
                                    <inertial pos="0.0111341 0.000167085 -0.0183736" quat="0.592187 0.382894 0.382294 0.597125" mass="0.62347" diaginertia="0.00108535 0.000979327 0.000474977" />
                                    <joint name="leg_l6_joint" pos="0 0 0" axis="1 0 0" limited="true" range="-1 1" />
                                    <geom type="mesh" contype="0" conaffinity="0" group="1" rgba="0.89804 0.91765 0.92941 1" mesh="l_ankle_roll_link" />
                                    <geom class="collision" size="0.16 0.07 0.01" type="box" pos="0.02 0 -0.025" rgba="0.79216 0.81961 0.93333 1" />  
                                      <!-- <body name="leg_l_f1_link" pos="0.05 0.02 -0.05">
                                        <inertial pos="0 0 0" mass="0.01" diaginertia="1e-06 1e-06 1e-06"/>
                                        <geom class="foot1"/>
                                        <geom class="foot2"/>
                                        <geom class="foot3"/>
                                        <geom class="foot4"/>
                                        <site name="leg_l_f1_site" pos="0 0 0"/>
                                      </body>
                                      <body name="leg_l_f2_link" pos="0.05 -0.02 -0.05">
                                        <inertial pos="0 0 0" mass="0.01" diaginertia="1e-06 1e-06 1e-06"/>
                                        <geom class="foot1"/>
                                        <geom class="foot2"/>
                                        <geom class="foot3"/>
                                        <geom class="foot4"/>
                                        <site name="leg_l_f2_site" pos="0 0 0"/>
                                      </body>
                                      <body name="leg_l_f3_link" pos="-0.07 0.02 -0.05">
                                        <inertial pos="0 0 0" mass="0.01" diaginertia="1e-06 1e-06 1e-06"/>
                                        <geom class="foot1"/>
                                        <geom class="foot2"/>
                                        <geom class="foot3"/>
                                        <geom class="foot4"/>
                                        <site name="leg_l_f3_site" pos="0 0 0"/>
                                      </body>
                                      <body name="leg_l_f4_link" pos="-0.07 -0.02 -0.05">
                                        <inertial pos="0 0 0" mass="0.01" diaginertia="1e-06 1e-06 1e-06"/>
                                        <geom class="foot1"/>
                                        <geom class="foot2"/>
                                        <geom class="foot3"/>
                                        <geom class="foot4"/>
                                        <site name="leg_l_f4_site" pos="0 0 0"/>
                                      </body> -->
                                </body>
                            </body>
                        </body>
                    </body>
                </body>
            </body>
            <body name="leg_r1_link" pos="-0.0028186 -0.0482 -0.031">
                <inertial pos="0.0010765 -0.030923 -0.00028479" quat="0.0142487 0.688307 0.103743 0.717822" mass="0.37475" diaginertia="0.000203872 0.000193061 0.000188317" />
                <joint name="leg_r1_joint" pos="0 0 0" axis="0 1 0" limited="true" range="-1.5 1.5" />
                <geom type="mesh" contype="0" conaffinity="0" group="1" rgba="0.79216 0.81961 0.93333 1" mesh="r_hip_pitch_link" />
                <geom size="0.0005 0.0005 0.0005" type="box" rgba="0.79216 0.81961 0.93333 1" />
                <body name="leg_r2_link" pos="0.0245 -0.032 0">
                    <inertial pos="-0.025798 0.00024695 -0.059965" quat="0.712751 -0.0772627 -0.0796054 0.692589" mass="0.41506" diaginertia="0.000442349 0.000383181 0.000238861" />
                    <joint name="leg_r2_joint" pos="0 0 0" axis="1 0 0" limited="true" range="-1.5 1.5" />
                    <geom type="mesh" contype="0" conaffinity="0" group="1" rgba="0.79216 0.81961 0.93333 1" mesh="r_hip_roll_link" />
                    <geom size="0.0005 0.0005 0.0005" type="box" rgba="0.79216 0.81961 0.93333 1" />
                    <body name="leg_r3_link" pos="-0.0245 0 -0.0935">
                        <inertial pos="0 0.00287888 -0.0254156" quat="0.773954 0.633242 0 0" mass="0.120981" diaginertia="0.00013404 0.000100211 6.29595e-05" />
                        <joint name="leg_r3_joint" pos="0 0 0" axis="0 0 1" limited="true" range="-1.5 1.5" />
                        <geom type="mesh" contype="0" conaffinity="0" group="1" rgba="0.89804 0.91765 0.92941 1" mesh="r_thigh_link" />
                        <geom size="0.0005 0.0005 0.0005" type="box" rgba="0.89804 0.91765 0.92941 1" />
                        <body name="leg_r4_link" pos="0 -0.0275 -0.046">
                            <inertial pos="4.686e-05 0.024357 -0.0698324" quat="0.705543 -0.000997519 -0.00114574 0.708665" mass="0.760191" diaginertia="0.00327684 0.0032569 0.000316823" />
                            <joint name="leg_r4_joint" pos="0 0 0" axis="0 1 0" limited="true" range="-1 3" />
                            <geom type="mesh" contype="0" conaffinity="0" group="1" rgba="0.79216 0.81961 0.93333 1" mesh="r_calf_link" />
                            <geom size="0.0005 0.0005 0.0005" type="box" rgba="0.79216 0.81961 0.93333 1" />
                            <body name="leg_r5_link" pos="0 0 -0.14">
                                <inertial pos="0.0257768 0.0285458 0" quat="0.468217 0.52988 -0.468217 0.52988" mass="0.132231" diaginertia="0.00013716 9.89216e-05 6.97784e-05" />
                                <joint name="leg_r5_joint" pos="0 0 0" axis="0 1 0" limited="true" range="-1 1" />
                                <geom type="mesh" contype="0" conaffinity="0" group="1" rgba="0.89804 0.91765 0.92941 1" mesh="r_ankle_pitch_link" />
                                <geom size="0.0005 0.0005 0.0005" type="box" rgba="0.89804 0.91765 0.92941 1" />
                                <body name="r_ankle_roll_link" pos="0.051 0.0275 0">
                                    <inertial pos="0.0111341 0.000167085 -0.0183736" quat="0.592187 0.382894 0.382294 0.597125" mass="0.62347" diaginertia="0.00108535 0.000979327 0.000474977" />
                                    <joint name="leg_r6_joint" pos="0 0 0" axis="1 0 0" limited="true" range="-1 1" />
                                    <geom type="mesh" contype="0" conaffinity="0" group="1" rgba="0.79216 0.81961 0.93333 1" mesh="r_ankle_roll_link" />
                                    <geom class="collision" size="0.16 0.07 0.01" type="box" pos="0.02 0 -0.025" rgba="0.79216 0.81961 0.93333 1" />     
                                    <!-- <body name="leg_r_f1_link" pos="0.05 0.02 -0.05">
                                        <inertial pos="0 0 0" mass="0.01" diaginertia="1e-06 1e-06 1e-06"/>
                                        <geom class="foot1"/>
                                        <geom class="foot2"/>
                                        <geom class="foot3"/>
                                        <geom class="foot4"/>
                                        <site name="leg_r_f1_site" pos="0 0 0"/>
                                    </body>
                                    <body name="leg_r_f2_link" pos="0.05 -0.02 -0.05">
                                        <inertial pos="0 0 0" mass="0.01" diaginertia="1e-06 1e-06 1e-06"/>
                                        <geom class="foot1"/>
                                        <geom class="foot2"/>
                                        <geom class="foot3"/>
                                        <geom class="foot4"/>
                                        <site name="leg_r_f2_site" pos="0 0 0"/>
                                    </body>
                                    <body name="leg_r_f3_link" pos="-0.07 0.02 -0.05">
                                        <inertial pos="0 0 0" mass="0.01" diaginertia="1e-06 1e-06 1e-06"/>
                                        <geom class="foot1"/>
                                        <geom class="foot2"/>
                                        <geom class="foot3"/>
                                        <geom class="foot4"/>
                                        <site name="leg_r_f3_site" pos="0 0 0"/>
                                    </body>    
                                    <body name="leg_r_f4_link" pos="-0.07 -0.02 -0.05">
                                        <inertial pos="0 0 0" mass="0.01" diaginertia="1e-06 1e-06 1e-06"/>
                                        <geom class="foot1"/>
                                        <geom class="foot2"/>
                                        <geom class="foot3"/>
                                        <geom class="foot4"/>
                                        <site name="leg_r_f4_site" pos="0 0 0"/>
                                    </body>                  -->
                                </body>
                            </body>
                        </body>
                    </body>
                </body>
            </body>
        </body>
  </worldbody>

  <actuator>
    <motor class="hunter_motor" name="leg_l1_joint" joint="leg_l1_joint"/>
    <motor class="hunter_motor" name="leg_l2_joint" joint="leg_l2_joint"/>
    <motor class="hunter_motor" name="leg_l3_joint" joint="leg_l3_joint"/>
    <motor class="hunter_motor" name="leg_l4_joint" joint="leg_l4_joint"/>
    <motor class="hunter_motor" name="leg_l5_joint" joint="leg_l5_joint"/>
    <motor class="hunter_motor" name="leg_l6_joint" joint="leg_l6_joint"/>

    <motor class="hunter_motor" name="leg_r1_joint" joint="leg_r1_joint"/>  
    <motor class="hunter_motor" name="leg_r2_joint" joint="leg_r2_joint"/>
    <motor class="hunter_motor" name="leg_r3_joint" joint="leg_r3_joint"/>
    <motor class="hunter_motor" name="leg_r4_joint" joint="leg_r4_joint"/>
    <motor class="hunter_motor" name="leg_r5_joint" joint="leg_r5_joint"/>
    <motor class="hunter_motor" name="leg_r6_joint" joint="leg_r6_joint"/>

  </actuator>

  <sensor>
    <accelerometer name="accel" site="imu"/>
    <gyro name="gyro" site="imu"/>

    <!-- <touch name="touch_L_f1" site="leg_l_f1_site"/>
    <touch name="touch_L_f2" site="leg_l_f2_site"/>
    <touch name="touch_L_f3" site="leg_l_f3_site"/>
    <touch name="touch_L_f4" site="leg_l_f4_site"/>
    <touch name="touch_R_f1" site="leg_r_f1_site"/>
    <touch name="touch_R_f2" site="leg_r_f2_site"/>
    <touch name="touch_R_f3" site="leg_r_f3_site"/>
    <touch name="touch_R_f4" site="leg_r_f4_site"/> -->
    

    <jointpos name="jpos_L1" joint="leg_l1_joint" />
    <jointpos name="jpos_L2" joint="leg_l2_joint" />
    <jointpos name="jpos_L3" joint="leg_l3_joint" />
    <jointpos name="jpos_L4" joint="leg_l4_joint" />
    <jointpos name="jpos_L5" joint="leg_l5_joint" />
    <jointpos name="jpos_L6" joint="leg_l6_joint" />
    <jointpos name="jpos_R1" joint="leg_r1_joint" />
    <jointpos name="jpos_R2" joint="leg_r2_joint" />
    <jointpos name="jpos_R3" joint="leg_r3_joint" />
    <jointpos name="jpos_R4" joint="leg_r4_joint" />
    <jointpos name="jpos_R5" joint="leg_r5_joint" />
    <jointpos name="jpos_R6" joint="leg_r6_joint" />

    <jointvel name="jvel_L1" joint="leg_l1_joint" />
    <jointvel name="jvel_L2" joint="leg_l2_joint" />
    <jointvel name="jvel_L3" joint="leg_l3_joint" />
    <jointvel name="jvel_L4" joint="leg_l4_joint" />
    <jointvel name="jvel_L5" joint="leg_l5_joint" />
    <jointvel name="jvel_L6" joint="leg_l6_joint" />
    <jointvel name="jvel_R1" joint="leg_r1_joint" />
    <jointvel name="jvel_R2" joint="leg_r2_joint" />
    <jointvel name="jvel_R3" joint="leg_r3_joint" />
    <jointvel name="jvel_R4" joint="leg_r4_joint" />
    <jointvel name="jvel_R5" joint="leg_r5_joint" />
    <jointvel name="jvel_R6" joint="leg_r6_joint" />
  </sensor>

</mujoco>